Workbook

Sheet Instructions
A1: Attendance & Vacation Tracker 2026
A2: Internal attendance, vacation and sick leave record. Calendar year 2026.
A4: How it works
A5: Sunday - Thursday | B5: Automatically Present from the default start to the default end time (08:00 - 16:30 = 8.5 hours). Nothing needs to be entered.
A6: Friday and Saturday | B6: No automatic hours. Enter Manual Work with start and end time if work was done. Saturday work is entered by the administrator only.
A7: Holidays | B7: No automatic work. Vacation and sick leave cannot be recorded on a holiday. Holidays are not counted as working days.
A8: Holiday eve | B8: Automatic work until 14:00. A full vacation day on a holiday eve counts as half a vacation day.
A9: Partial leave | B9: Day equivalent = leave hours / 8.5. Example: 4.25 hours = 0.50 day.
A11: What to fill in
A12: Yellow cells, blue text | B12: Input cells. Everything else is calculated and protected.
A13: Status | B13: Leave empty for an automatic day. Choose from the list only when the day is different.
A14: Start / End | B14: Working hours (hh:mm). Required for Manual Work. Optional for partial leave (the hours actually worked).
A15: Leave from / Leave to | B15: Required for Partial Vacation and Partial Sick Leave.
A16: Notes | B16: Optional, e.g. Doctor appointment, Annual vacation, Personal leave.
A17: Check column | B17: Shows a message when an entry is incomplete or not allowed. Such entries are not counted.
A19: Adding an employee
A20: Step 1 | B20: Right-click an employee sheet tab > Move or Copy > Create a copy.
A21: Step 2 | B21: Rename the new sheet to the employee full name, then clear the yellow input cells (columns E - J).
A22: Step 3 | B22: Add the same name to the Employees sheet. The reports and the dashboard pick it up automatically.
A24: Sharing
A25: Recommended | B25: Keep the file on OneDrive or SharePoint so everyone edits the same copy. Version history there serves as the change log.
A26: Limitation | B26: Excel cannot restrict access per employee: everyone with access to the file can see and edit every sheet.
A28: Example entry
A29: Partial vacation | C29: Date | D29: Status | E29: Start | F29: End | G29: Leave from | H29: Leave to | I29: Notes | J29: Worked hours | K29: Vacation hours | L29: Vacation days
A30: Works 08:00-12:00, vacation 12:00-16:30 | C30: 46027 | D30: Partial Vacation | E30: 0.33333333 | F30: 0.5 | G30: 0.5 | H30: 0.6875 | I30: Doctor appointment | J30: =(F30-E30)*24 -> 4 | K30: =(H30-G30)*24 -> 4.5 | L30: =K30/Settings!$B$9 -> 0.52941176
A31: Illustration only - the example is not part of any employee record.

Sheet Dashboard
A1: Dashboard 2026
A2: Vacation and sick leave usage per employee. Updates automatically.
A3: Current month | B3: =INDEX(Lists!$B$1:$B$12,J3)&" 2026" -> October 2026 | D3: =IF(YEAR(TODAY())=2026,TODAY(),DATE(2026,12,31)) -> 46310 | J3: =IF(YEAR(TODAY())=2026,MONTH(TODAY()),IF(YEAR(TODAY())<2026,1,12)) -> 10
A5: Employee | B5: Vacation days 2026 | C5: Vacation hours 2026 | D5: Sick leave days 2026 | E5: Sick leave hours 2026 | F5: Days worked this month (to date) | G5: Working days this month | H5: Entries to check
A6: =IF(Employees!A5="","",Employees!A5) -> Tomer Cohen | B6: =IF($A6="","",IFERROR(SUM(INDIRECT("'"&$A6&"'!$Q$7:$Q$371")),"Sheet missing")) -> 0 | C6: =IF($A6="","",IFERROR(SUM(INDIRECT("'"&$A6&"'!$O$7:$O$371")),"Sheet missing")) -> 0 | D6: =IF($A6="","",IFERROR(SUM(INDIRECT("'"&$A6&"'!$R$7:$R$371")),"Sheet missing")) -> 0 | E6: =IF($A6="","",IFERROR(SUM(INDIRECT("'"&$A6&"'!$P$7:$P$371")),"Sheet missing")) -> 0 | F6: =IF($A6="","",IFERROR(COUNTIFS(INDIRECT("'"&$A6&"'!$T$7:$T$371"),$J$3,INDIRECT("'"&$A6&"'!$N$7:$N$371"),">0",INDIRECT("'"&$A6&"'!$A$7:$A$371"),"<="&$D$3),"Sheet missing")) -> 11 | G6: =IF($A6="","",IFERROR(COUNTIFS(INDIRECT("'"&$A6&"'!$T$7:$T$371"),$J$3,INDIRECT("'"&$A6&"'!$U$7:$U$371"),TRUE()),"Sheet missing")) -> 21 | H6: =IF($A6="","",IFERROR(COUNTIF(INDIRECT("'"&$A6&"'!$S$7:$S$371"),"?*"),"Sheet missing")) -> 0
A7: =IF(Employees!A6="","",Employees!A6) -> Nir Ben Haim | B7: =IF($A7="","",IFERROR(SUM(INDIRECT("'"&$A7&"'!$Q$7:$Q$371")),"Sheet missing")) -> 0 | C7: =IF($A7="","",IFERROR(SUM(INDIRECT("'"&$A7&"'!$O$7:$O$371")),"Sheet missing")) -> 0 | D7: =IF($A7="","",IFERROR(SUM(INDIRECT("'"&$A7&"'!$R$7:$R$371")),"Sheet missing")) -> 0 | E7: =IF($A7="","",IFERROR(SUM(INDIRECT("'"&$A7&"'!$P$7:$P$371")),"Sheet missing")) -> 0 | F7: =IF($A7="","",IFERROR(COUNTIFS(INDIRECT("'"&$A7&"'!$T$7:$T$371"),$J$3,INDIRECT("'"&$A7&"'!$N$7:$N$371"),">0",INDIRECT("'"&$A7&"'!$A$7:$A$371"),"<="&$D$3),"Sheet missing")) -> 11 | G7: =IF($A7="","",IFERROR(COUNTIFS(INDIRECT("'"&$A7&"'!$T$7:$T$371"),$J$3,INDIRECT("'"&$A7&"'!$U$7:$U$371"),TRUE()),"Sheet missing")) -> 21 | H7: =IF($A7="","",IFERROR(COUNTIF(INDIRECT("'"&$A7&"'!$S$7:$S$371"),"?*"),"Sheet missing")) -> 0
A8: =IF(Employees!A7="","",Employees!A7) -> Jonatan Ben Sudai | B8: =IF($A8="","",IFERROR(SUM(INDIRECT("'"&$A8&"'!$Q$7:$Q$371")),"Sheet missing")) -> 0 | C8: =IF($A8="","",IFERROR(SUM(INDIRECT("'"&$A8&"'!$O$7:$O$371")),"Sheet missing")) -> 0 | D8: =IF($A8="","",IFERROR(SUM(INDIRECT("'"&$A8&"'!$R$7:$R$371")),"Sheet missing")) -> 0 | E8: =IF($A8="","",IFERROR(SUM(INDIRECT("'"&$A8&"'!$P$7:$P$371")),"Sheet missing")) -> 0 | F8: =IF($A8="","",IFERROR(COUNTIFS(INDIRECT("'"&$A8&"'!$T$7:$T$371"),$J$3,INDIRECT("'"&$A8&"'!$N$7:$N$371"),">0",INDIRECT("'"&$A8&"'!$A$7:$A$371"),"<="&$D$3),"Sheet missing")) -> 11 | G8: =IF($A8="","",IFERROR(COUNTIFS(INDIRECT("'"&$A8&"'!$T$7:$T$371"),$J$3,INDIRECT("'"&$A8&"'!$U$7:$U$371"),TRUE()),"Sheet missing")) -> 21 | H8: =IF($A8="","",IFERROR(COUNTIF(INDIRECT("'"&$A8&"'!$S$7:$S$371"),"?*"),"Sheet missing")) -> 0
A9: =IF(Employees!A8="","",Employees!A8) | B9: =IF($A9="","",IFERROR(SUM(INDIRECT("'"&$A9&"'!$Q$7:$Q$371")),"Sheet missing")) | C9: =IF($A9="","",IFERROR(SUM(INDIRECT("'"&$A9&"'!$O$7:$O$371")),"Sheet missing")) | D9: =IF($A9="","",IFERROR(SUM(INDIRECT("'"&$A9&"'!$R$7:$R$371")),"Sheet missing")) | E9: =IF($A9="","",IFERROR(SUM(INDIRECT("'"&$A9&"'!$P$7:$P$371")),"Sheet missing")) | F9: =IF($A9="","",IFERROR(COUNTIFS(INDIRECT("'"&$A9&"'!$T$7:$T$371"),$J$3,INDIRECT("'"&$A9&"'!$N$7:$N$371"),">0",INDIRECT("'"&$A9&"'!$A$7:$A$371"),"<="&$D$3),"Sheet missing")) | G9: =IF($A9="","",IFERROR(COUNTIFS(INDIRECT("'"&$A9&"'!$T$7:$T$371"),$J$3,INDIRECT("'"&$A9&"'!$U$7:$U$371"),TRUE()),"Sheet missing")) | H9: =IF($A9="","",IFERROR(COUNTIF(INDIRECT("'"&$A9&"'!$S$7:$S$371"),"?*"),"Sheet missing"))
A10: =IF(Employees!A9="","",Employees!A9) | B10: =IF($A10="","",IFERROR(SUM(INDIRECT("'"&$A10&"'!$Q$7:$Q$371")),"Sheet missing")) | C10: =IF($A10="","",IFERROR(SUM(INDIRECT("'"&$A10&"'!$O$7:$O$371")),"Sheet missing")) | D10: =IF($A10="","",IFERROR(SUM(INDIRECT("'"&$A10&"'!$R$7:$R$371")),"Sheet missing")) | E10: =IF($A10="","",IFERROR(SUM(INDIRECT("'"&$A10&"'!$P$7:$P$371")),"Sheet missing")) | F10: =IF($A10="","",IFERROR(COUNTIFS(INDIRECT("'"&$A10&"'!$T$7:$T$371"),$J$3,INDIRECT("'"&$A10&"'!$N$7:$N$371"),">0",INDIRECT("'"&$A10&"'!$A$7:$A$371"),"<="&$D$3),"Sheet missing")) | G10: =IF($A10="","",IFERROR(COUNTIFS(INDIRECT("'"&$A10&"'!$T$7:$T$371"),$J$3,INDIRECT("'"&$A10&"'!$U$7:$U$371"),TRUE()),"Sheet missing")) | H10: =IF($A10="","",IFERROR(COUNTIF(INDIRECT("'"&$A10&"'!$S$7:$S$371"),"?*"),"Sheet missing"))
A11: =IF(Employees!A10="","",Employees!A10) | B11: =IF($A11="","",IFERROR(SUM(INDIRECT("'"&$A11&"'!$Q$7:$Q$371")),"Sheet missing")) | C11: =IF($A11="","",IFERROR(SUM(INDIRECT("'"&$A11&"'!$O$7:$O$371")),"Sheet missing")) | D11: =IF($A11="","",IFERROR(SUM(INDIRECT("'"&$A11&"'!$R$7:$R$371")),"Sheet missing")) | E11: =IF($A11="","",IFERROR(SUM(INDIRECT("'"&$A11&"'!$P$7:$P$371")),"Sheet missing")) | F11: =IF($A11="","",IFERROR(COUNTIFS(INDIRECT("'"&$A11&"'!$T$7:$T$371"),$J$3,INDIRECT("'"&$A11&"'!$N$7:$N$371"),">0",INDIRECT("'"&$A11&"'!$A$7:$A$371"),"<="&$D$3),"Sheet missing")) | G11: =IF($A11="","",IFERROR(COUNTIFS(INDIRECT("'"&$A11&"'!$T$7:$T$371"),$J$3,INDIRECT("'"&$A11&"'!$U$7:$U$371"),TRUE()),"Sheet missing")) | H11: =IF($A11="","",IFERROR(COUNTIF(INDIRECT("'"&$A11&"'!$S$7:$S$371"),"?*"),"Sheet missing"))
A12: =IF(Employees!A11="","",Employees!A11) | B12: =IF($A12="","",IFERROR(SUM(INDIRECT("'"&$A12&"'!$Q$7:$Q$371")),"Sheet missing")) | C12: =IF($A12="","",IFERROR(SUM(INDIRECT("'"&$A12&"'!$O$7:$O$371")),"Sheet missing")) | D12: =IF($A12="","",IFERROR(SUM(INDIRECT("'"&$A12&"'!$R$7:$R$371")),"Sheet missing")) | E12: =IF($A12="","",IFERROR(SUM(INDIRECT("'"&$A12&"'!$P$7:$P$371")),"Sheet missing")) | F12: =IF($A12="","",IFERROR(COUNTIFS(INDIRECT("'"&$A12&"'!$T$7:$T$371"),$J$3,INDIRECT("'"&$A12&"'!$N$7:$N$371"),">0",INDIRECT("'"&$A12&"'!$A$7:$A$371"),"<="&$D$3),"Sheet missing")) | G12: =IF($A12="","",IFERROR(COUNTIFS(INDIRECT("'"&$A12&"'!$T$7:$T$371"),$J$3,INDIRECT("'"&$A12&"'!$U$7:$U$371"),TRUE()),"Sheet missing")) | H12: =IF($A12="","",IFERROR(COUNTIF(INDIRECT("'"&$A12&"'!$S$7:$S$371"),"?*"),"Sheet missing"))
A13: =IF(Employees!A12="","",Employees!A12) | B13: =IF($A13="","",IFERROR(SUM(INDIRECT("'"&$A13&"'!$Q$7:$Q$371")),"Sheet missing")) | C13: =IF($A13="","",IFERROR(SUM(INDIRECT("'"&$A13&"'!$O$7:$O$371")),"Sheet missing")) | D13: =IF($A13="","",IFERROR(SUM(INDIRECT("'"&$A13&"'!$R$7:$R$371")),"Sheet missing")) | E13: =IF($A13="","",IFERROR(SUM(INDIRECT("'"&$A13&"'!$P$7:$P$371")),"Sheet missing")) | F13: =IF($A13="","",IFERROR(COUNTIFS(INDIRECT("'"&$A13&"'!$T$7:$T$371"),$J$3,INDIRECT("'"&$A13&"'!$N$7:$N$371"),">0",INDIRECT("'"&$A13&"'!$A$7:$A$371"),"<="&$D$3),"Sheet missing")) | G13: =IF($A13="","",IFERROR(COUNTIFS(INDIRECT("'"&$A13&"'!$T$7:$T$371"),$J$3,INDIRECT("'"&$A13&"'!$U$7:$U$371"),TRUE()),"Sheet missing")) | H13: =IF($A13="","",IFERROR(COUNTIF(INDIRECT("'"&$A13&"'!$S$7:$S$371"),"?*"),"Sheet missing"))
A14: =IF(Employees!A13="","",Employees!A13) | B14: =IF($A14="","",IFERROR(SUM(INDIRECT("'"&$A14&"'!$Q$7:$Q$371")),"Sheet missing")) | C14: =IF($A14="","",IFERROR(SUM(INDIRECT("'"&$A14&"'!$O$7:$O$371")),"Sheet missing")) | D14: =IF($A14="","",IFERROR(SUM(INDIRECT("'"&$A14&"'!$R$7:$R$371")),"Sheet missing")) | E14: =IF($A14="","",IFERROR(SUM(INDIRECT("'"&$A14&"'!$P$7:$P$371")),"Sheet missing")) | F14: =IF($A14="","",IFERROR(COUNTIFS(INDIRECT("'"&$A14&"'!$T$7:$T$371"),$J$3,INDIRECT("'"&$A14&"'!$N$7:$N$371"),">0",INDIRECT("'"&$A14&"'!$A$7:$A$371"),"<="&$D$3),"Sheet missing")) | G14: =IF($A14="","",IFERROR(COUNTIFS(INDIRECT("'"&$A14&"'!$T$7:$T$371"),$J$3,INDIRECT("'"&$A14&"'!$U$7:$U$371"),TRUE()),"Sheet missing")) | H14: =IF($A14="","",IFERROR(COUNTIF(INDIRECT("'"&$A14&"'!$S$7:$S$371"),"?*"),"Sheet missing"))
A15: =IF(Employees!A14="","",Employees!A14) | B15: =IF($A15="","",IFERROR(SUM(INDIRECT("'"&$A15&"'!$Q$7:$Q$371")),"Sheet missing")) | C15: =IF($A15="","",IFERROR(SUM(INDIRECT("'"&$A15&"'!$O$7:$O$371")),"Sheet missing")) | D15: =IF($A15="","",IFERROR(SUM(INDIRECT("'"&$A15&"'!$R$7:$R$371")),"Sheet missing")) | E15: =IF($A15="","",IFERROR(SUM(INDIRECT("'"&$A15&"'!$P$7:$P$371")),"Sheet missing")) | F15: =IF($A15="","",IFERROR(COUNTIFS(INDIRECT("'"&$A15&"'!$T$7:$T$371"),$J$3,INDIRECT("'"&$A15&"'!$N$7:$N$371"),">0",INDIRECT("'"&$A15&"'!$A$7:$A$371"),"<="&$D$3),"Sheet missing")) | G15: =IF($A15="","",IFERROR(COUNTIFS(INDIRECT("'"&$A15&"'!$T$7:$T$371"),$J$3,INDIRECT("'"&$A15&"'!$U$7:$U$371"),TRUE()),"Sheet missing")) | H15: =IF($A15="","",IFERROR(COUNTIF(INDIRECT("'"&$A15&"'!$S$7:$S$371"),"?*"),"Sheet missing"))
A16: Total | B16: =SUM(B6:B15) -> 0 | C16: =SUM(C6:C15) -> 0 | D16: =SUM(D6:D15) -> 0 | E16: =SUM(E6:E15) -> 0 | H16: =SUM(H6:H15) -> 0
A18: Vacation days by month
A19: Employee | B19: Jan | C19: Feb | D19: Mar | E19: Apr | F19: May | G19: Jun | H19: Jul | I19: Aug | J19: Sep | K19: Oct | L19: Nov | M19: Dec | N19: Total
A20: =$A6 -> Tomer Cohen | B20: =IF($A20="","",IFERROR(SUMIFS(INDIRECT("'"&$A20&"'!$Q$7:$Q$371"),INDIRECT("'"&$A20&"'!$T$7:$T$371"),1),"-")) -> 0 | C20: =IF($A20="","",IFERROR(SUMIFS(INDIRECT("'"&$A20&"'!$Q$7:$Q$371"),INDIRECT("'"&$A20&"'!$T$7:$T$371"),2),"-")) -> 0 | D20: =IF($A20="","",IFERROR(SUMIFS(INDIRECT("'"&$A20&"'!$Q$7:$Q$371"),INDIRECT("'"&$A20&"'!$T$7:$T$371"),3),"-")) -> 0 | E20: =IF($A20="","",IFERROR(SUMIFS(INDIRECT("'"&$A20&"'!$Q$7:$Q$371"),INDIRECT("'"&$A20&"'!$T$7:$T$371"),4),"-")) -> 0 | F20: =IF($A20="","",IFERROR(SUMIFS(INDIRECT("'"&$A20&"'!$Q$7:$Q$371"),INDIRECT("'"&$A20&"'!$T$7:$T$371"),5),"-")) -> 0 | G20: =IF($A20="","",IFERROR(SUMIFS(INDIRECT("'"&$A20&"'!$Q$7:$Q$371"),INDIRECT("'"&$A20&"'!$T$7:$T$371"),6),"-")) -> 0 | H20: =IF($A20="","",IFERROR(SUMIFS(INDIRECT("'"&$A20&"'!$Q$7:$Q$371"),INDIRECT("'"&$A20&"'!$T$7:$T$371"),7),"-")) -> 0 | I20: =IF($A20="","",IFERROR(SUMIFS(INDIRECT("'"&$A20&"'!$Q$7:$Q$371"),INDIRECT("'"&$A20&"'!$T$7:$T$371"),8),"-")) -> 0 | J20: =IF($A20="","",IFERROR(SUMIFS(INDIRECT("'"&$A20&"'!$Q$7:$Q$371"),INDIRECT("'"&$A20&"'!$T$7:$T$371"),9),"-")) -> 0 | K20: =IF($A20="","",IFERROR(SUMIFS(INDIRECT("'"&$A20&"'!$Q$7:$Q$371"),INDIRECT("'"&$A20&"'!$T$7:$T$371"),10),"-")) -> 0 | L20: =IF($A20="","",IFERROR(SUMIFS(INDIRECT("'"&$A20&"'!$Q$7:$Q$371"),INDIRECT("'"&$A20&"'!$T$7:$T$371"),11),"-")) -> 0 | M20: =IF($A20="","",IFERROR(SUMIFS(INDIRECT("'"&$A20&"'!$Q$7:$Q$371"),INDIRECT("'"&$A20&"'!$T$7:$T$371"),12),"-")) -> 0 | N20: =IF($A20="","",SUM(B20:M20)) -> 0
A21: =$A7 -> Nir Ben Haim | B21: =IF($A21="","",IFERROR(SUMIFS(INDIRECT("'"&$A21&"'!$Q$7:$Q$371"),INDIRECT("'"&$A21&"'!$T$7:$T$371"),1),"-")) -> 0 | C21: =IF($A21="","",IFERROR(SUMIFS(INDIRECT("'"&$A21&"'!$Q$7:$Q$371"),INDIRECT("'"&$A21&"'!$T$7:$T$371"),2),"-")) -> 0 | D21: =IF($A21="","",IFERROR(SUMIFS(INDIRECT("'"&$A21&"'!$Q$7:$Q$371"),INDIRECT("'"&$A21&"'!$T$7:$T$371"),3),"-")) -> 0 | E21: =IF($A21="","",IFERROR(SUMIFS(INDIRECT("'"&$A21&"'!$Q$7:$Q$371"),INDIRECT("'"&$A21&"'!$T$7:$T$371"),4),"-")) -> 0 | F21: =IF($A21="","",IFERROR(SUMIFS(INDIRECT("'"&$A21&"'!$Q$7:$Q$371"),INDIRECT("'"&$A21&"'!$T$7:$T$371"),5),"-")) -> 0 | G21: =IF($A21="","",IFERROR(SUMIFS(INDIRECT("'"&$A21&"'!$Q$7:$Q$371"),INDIRECT("'"&$A21&"'!$T$7:$T$371"),6),"-")) -> 0 | H21: =IF($A21="","",IFERROR(SUMIFS(INDIRECT("'"&$A21&"'!$Q$7:$Q$371"),INDIRECT("'"&$A21&"'!$T$7:$T$371"),7),"-")) -> 0 | I21: =IF($A21="","",IFERROR(SUMIFS(INDIRECT("'"&$A21&"'!$Q$7:$Q$371"),INDIRECT("'"&$A21&"'!$T$7:$T$371"),8),"-")) -> 0 | J21: =IF($A21="","",IFERROR(SUMIFS(INDIRECT("'"&$A21&"'!$Q$7:$Q$371"),INDIRECT("'"&$A21&"'!$T$7:$T$371"),9),"-")) -> 0 | K21: =IF($A21="","",IFERROR(SUMIFS(INDIRECT("'"&$A21&"'!$Q$7:$Q$371"),INDIRECT("'"&$A21&"'!$T$7:$T$371"),10),"-")) -> 0 | L21: =IF($A21="","",IFERROR(SUMIFS(INDIRECT("'"&$A21&"'!$Q$7:$Q$371"),INDIRECT("'"&$A21&"'!$T$7:$T$371"),11),"-")) -> 0 | M21: =IF($A21="","",IFERROR(SUMIFS(INDIRECT("'"&$A21&"'!$Q$7:$Q$371"),INDIRECT("'"&$A21&"'!$T$7:$T$371"),12),"-")) -> 0 | N21: =IF($A21="","",SUM(B21:M21)) -> 0
A22: =$A8 -> Jonatan Ben Sudai | B22: =IF($A22="","",IFERROR(SUMIFS(INDIRECT("'"&$A22&"'!$Q$7:$Q$371"),INDIRECT("'"&$A22&"'!$T$7:$T$371"),1),"-")) -> 0 | C22: =IF($A22="","",IFERROR(SUMIFS(INDIRECT("'"&$A22&"'!$Q$7:$Q$371"),INDIRECT("'"&$A22&"'!$T$7:$T$371"),2),"-")) -> 0 | D22: =IF($A22="","",IFERROR(SUMIFS(INDIRECT("'"&$A22&"'!$Q$7:$Q$371"),INDIRECT("'"&$A22&"'!$T$7:$T$371"),3),"-")) -> 0 | E22: =IF($A22="","",IFERROR(SUMIFS(INDIRECT("'"&$A22&"'!$Q$7:$Q$371"),INDIRECT("'"&$A22&"'!$T$7:$T$371"),4),"-")) -> 0 | F22: =IF($A22="","",IFERROR(SUMIFS(INDIRECT("'"&$A22&"'!$Q$7:$Q$371"),INDIRECT("'"&$A22&"'!$T$7:$T$371"),5),"-")) -> 0 | G22: =IF($A22="","",IFERROR(SUMIFS(INDIRECT("'"&$A22&"'!$Q$7:$Q$371"),INDIRECT("'"&$A22&"'!$T$7:$T$371"),6),"-")) -> 0 | H22: =IF($A22="","",IFERROR(SUMIFS(INDIRECT("'"&$A22&"'!$Q$7:$Q$371"),INDIRECT("'"&$A22&"'!$T$7:$T$371"),7),"-")) -> 0 | I22: =IF($A22="","",IFERROR(SUMIFS(INDIRECT("'"&$A22&"'!$Q$7:$Q$371"),INDIRECT("'"&$A22&"'!$T$7:$T$371"),8),"-")) -> 0 | J22: =IF($A22="","",IFERROR(SUMIFS(INDIRECT("'"&$A22&"'!$Q$7:$Q$371"),INDIRECT("'"&$A22&"'!$T$7:$T$371"),9),"-")) -> 0 | K22: =IF($A22="","",IFERROR(SUMIFS(INDIRECT("'"&$A22&"'!$Q$7:$Q$371"),INDIRECT("'"&$A22&"'!$T$7:$T$371"),10),"-")) -> 0 | L22: =IF($A22="","",IFERROR(SUMIFS(INDIRECT("'"&$A22&"'!$Q$7:$Q$371"),INDIRECT("'"&$A22&"'!$T$7:$T$371"),11),"-")) -> 0 | M22: =IF($A22="","",IFERROR(SUMIFS(INDIRECT("'"&$A22&"'!$Q$7:$Q$371"),INDIRECT("'"&$A22&"'!$T$7:$T$371"),12),"-")) -> 0 | N22: =IF($A22="","",SUM(B22:M22)) -> 0
A23: =$A9 | B23: =IF($A23="","",IFERROR(SUMIFS(INDIRECT("'"&$A23&"'!$Q$7:$Q$371"),INDIRECT("'"&$A23&"'!$T$7:$T$371"),1),"-")) | C23: =IF($A23="","",IFERROR(SUMIFS(INDIRECT("'"&$A23&"'!$Q$7:$Q$371"),INDIRECT("'"&$A23&"'!$T$7:$T$371"),2),"-")) | D23: =IF($A23="","",IFERROR(SUMIFS(INDIRECT("'"&$A23&"'!$Q$7:$Q$371"),INDIRECT("'"&$A23&"'!$T$7:$T$371"),3),"-")) | E23: =IF($A23="","",IFERROR(SUMIFS(INDIRECT("'"&$A23&"'!$Q$7:$Q$371"),INDIRECT("'"&$A23&"'!$T$7:$T$371"),4),"-")) | F23: =IF($A23="","",IFERROR(SUMIFS(INDIRECT("'"&$A23&"'!$Q$7:$Q$371"),INDIRECT("'"&$A23&"'!$T$7:$T$371"),5),"-")) | G23: =IF($A23="","",IFERROR(SUMIFS(INDIRECT("'"&$A23&"'!$Q$7:$Q$371"),INDIRECT("'"&$A23&"'!$T$7:$T$371"),6),"-")) | H23: =IF($A23="","",IFERROR(SUMIFS(INDIRECT("'"&$A23&"'!$Q$7:$Q$371"),INDIRECT("'"&$A23&"'!$T$7:$T$371"),7),"-")) | I23: =IF($A23="","",IFERROR(SUMIFS(INDIRECT("'"&$A23&"'!$Q$7:$Q$371"),INDIRECT("'"&$A23&"'!$T$7:$T$371"),8),"-")) | J23: =IF($A23="","",IFERROR(SUMIFS(INDIRECT("'"&$A23&"'!$Q$7:$Q$371"),INDIRECT("'"&$A23&"'!$T$7:$T$371"),9),"-")) | K23: =IF($A23="","",IFERROR(SUMIFS(INDIRECT("'"&$A23&"'!$Q$7:$Q$371"),INDIRECT("'"&$A23&"'!$T$7:$T$371"),10),"-")) | L23: =IF($A23="","",IFERROR(SUMIFS(INDIRECT("'"&$A23&"'!$Q$7:$Q$371"),INDIRECT("'"&$A23&"'!$T$7:$T$371"),11),"-")) | M23: =IF($A23="","",IFERROR(SUMIFS(INDIRECT("'"&$A23&"'!$Q$7:$Q$371"),INDIRECT("'"&$A23&"'!$T$7:$T$371"),12),"-")) | N23: =IF($A23="","",SUM(B23:M23))
A24: =$A10 | B24: =IF($A24="","",IFERROR(SUMIFS(INDIRECT("'"&$A24&"'!$Q$7:$Q$371"),INDIRECT("'"&$A24&"'!$T$7:$T$371"),1),"-")) | C24: =IF($A24="","",IFERROR(SUMIFS(INDIRECT("'"&$A24&"'!$Q$7:$Q$371"),INDIRECT("'"&$A24&"'!$T$7:$T$371"),2),"-")) | D24: =IF($A24="","",IFERROR(SUMIFS(INDIRECT("'"&$A24&"'!$Q$7:$Q$371"),INDIRECT("'"&$A24&"'!$T$7:$T$371"),3),"-")) | E24: =IF($A24="","",IFERROR(SUMIFS(INDIRECT("'"&$A24&"'!$Q$7:$Q$371"),INDIRECT("'"&$A24&"'!$T$7:$T$371"),4),"-")) | F24: =IF($A24="","",IFERROR(SUMIFS(INDIRECT("'"&$A24&"'!$Q$7:$Q$371"),INDIRECT("'"&$A24&"'!$T$7:$T$371"),5),"-")) | G24: =IF($A24="","",IFERROR(SUMIFS(INDIRECT("'"&$A24&"'!$Q$7:$Q$371"),INDIRECT("'"&$A24&"'!$T$7:$T$371"),6),"-")) | H24: =IF($A24="","",IFERROR(SUMIFS(INDIRECT("'"&$A24&"'!$Q$7:$Q$371"),INDIRECT("'"&$A24&"'!$T$7:$T$371"),7),"-")) | I24: =IF($A24="","",IFERROR(SUMIFS(INDIRECT("'"&$A24&"'!$Q$7:$Q$371"),INDIRECT("'"&$A24&"'!$T$7:$T$371"),8),"-")) | J24: =IF($A24="","",IFERROR(SUMIFS(INDIRECT("'"&$A24&"'!$Q$7:$Q$371"),INDIRECT("'"&$A24&"'!$T$7:$T$371"),9),"-")) | K24: =IF($A24="","",IFERROR(SUMIFS(INDIRECT("'"&$A24&"'!$Q$7:$Q$371"),INDIRECT("'"&$A24&"'!$T$7:$T$371"),10),"-")) | L24: =IF($A24="","",IFERROR(SUMIFS(INDIRECT("'"&$A24&"'!$Q$7:$Q$371"),INDIRECT("'"&$A24&"'!$T$7:$T$371"),11),"-")) | M24: =IF($A24="","",IFERROR(SUMIFS(INDIRECT("'"&$A24&"'!$Q$7:$Q$371"),INDIRECT("'"&$A24&"'!$T$7:$T$371"),12),"-")) | N24: =IF($A24="","",SUM(B24:M24))
A25: =$A11 | B25: =IF($A25="","",IFERROR(SUMIFS(INDIRECT("'"&$A25&"'!$Q$7:$Q$371"),INDIRECT("'"&$A25&"'!$T$7:$T$371"),1),"-")) | C25: =IF($A25="","",IFERROR(SUMIFS(INDIRECT("'"&$A25&"'!$Q$7:$Q$371"),INDIRECT("'"&$A25&"'!$T$7:$T$371"),2),"-")) | D25: =IF($A25="","",IFERROR(SUMIFS(INDIRECT("'"&$A25&"'!$Q$7:$Q$371"),INDIRECT("'"&$A25&"'!$T$7:$T$371"),3),"-")) | E25: =IF($A25="","",IFERROR(SUMIFS(INDIRECT("'"&$A25&"'!$Q$7:$Q$371"),INDIRECT("'"&$A25&"'!$T$7:$T$371"),4),"-")) | F25: =IF($A25="","",IFERROR(SUMIFS(INDIRECT("'"&$A25&"'!$Q$7:$Q$371"),INDIRECT("'"&$A25&"'!$T$7:$T$371"),5),"-")) | G25: =IF($A25="","",IFERROR(SUMIFS(INDIRECT("'"&$A25&"'!$Q$7:$Q$371"),INDIRECT("'"&$A25&"'!$T$7:$T$371"),6),"-")) | H25: =IF($A25="","",IFERROR(SUMIFS(INDIRECT("'"&$A25&"'!$Q$7:$Q$371"),INDIRECT("'"&$A25&"'!$T$7:$T$371"),7),"-")) | I25: =IF($A25="","",IFERROR(SUMIFS(INDIRECT("'"&$A25&"'!$Q$7:$Q$371"),INDIRECT("'"&$A25&"'!$T$7:$T$371"),8),"-")) | J25: =IF($A25="","",IFERROR(SUMIFS(INDIRECT("'"&$A25&"'!$Q$7:$Q$371"),INDIRECT("'"&$A25&"'!$T$7:$T$371"),9),"-")) | K25: =IF($A25="","",IFERROR(SUMIFS(INDIRECT("'"&$A25&"'!$Q$7:$Q$371"),INDIRECT("'"&$A25&"'!$T$7:$T$371"),10),"-")) | L25: =IF($A25="","",IFERROR(SUMIFS(INDIRECT("'"&$A25&"'!$Q$7:$Q$371"),INDIRECT("'"&$A25&"'!$T$7:$T$371"),11),"-")) | M25: =IF($A25="","",IFERROR(SUMIFS(INDIRECT("'"&$A25&"'!$Q$7:$Q$371"),INDIRECT("'"&$A25&"'!$T$7:$T$371"),12),"-")) | N25: =IF($A25="","",SUM(B25:M25))
A26: =$A12 | B26: =IF($A26="","",IFERROR(SUMIFS(INDIRECT("'"&$A26&"'!$Q$7:$Q$371"),INDIRECT("'"&$A26&"'!$T$7:$T$371"),1),"-")) | C26: =IF($A26="","",IFERROR(SUMIFS(INDIRECT("'"&$A26&"'!$Q$7:$Q$371"),INDIRECT("'"&$A26&"'!$T$7:$T$371"),2),"-")) | D26: =IF($A26="","",IFERROR(SUMIFS(INDIRECT("'"&$A26&"'!$Q$7:$Q$371"),INDIRECT("'"&$A26&"'!$T$7:$T$371"),3),"-")) | E26: =IF($A26="","",IFERROR(SUMIFS(INDIRECT("'"&$A26&"'!$Q$7:$Q$371"),INDIRECT("'"&$A26&"'!$T$7:$T$371"),4),"-")) | F26: =IF($A26="","",IFERROR(SUMIFS(INDIRECT("'"&$A26&"'!$Q$7:$Q$371"),INDIRECT("'"&$A26&"'!$T$7:$T$371"),5),"-")) | G26: =IF($A26="","",IFERROR(SUMIFS(INDIRECT("'"&$A26&"'!$Q$7:$Q$371"),INDIRECT("'"&$A26&"'!$T$7:$T$371"),6),"-")) | H26: =IF($A26="","",IFERROR(SUMIFS(INDIRECT("'"&$A26&"'!$Q$7:$Q$371"),INDIRECT("'"&$A26&"'!$T$7:$T$371"),7),"-")) | I26: =IF($A26="","",IFERROR(SUMIFS(INDIRECT("'"&$A26&"'!$Q$7:$Q$371"),INDIRECT("'"&$A26&"'!$T$7:$T$371"),8),"-")) | J26: =IF($A26="","",IFERROR(SUMIFS(INDIRECT("'"&$A26&"'!$Q$7:$Q$371"),INDIRECT("'"&$A26&"'!$T$7:$T$371"),9),"-")) | K26: =IF($A26="","",IFERROR(SUMIFS(INDIRECT("'"&$A26&"'!$Q$7:$Q$371"),INDIRECT("'"&$A26&"'!$T$7:$T$371"),10),"-")) | L26: =IF($A26="","",IFERROR(SUMIFS(INDIRECT("'"&$A26&"'!$Q$7:$Q$371"),INDIRECT("'"&$A26&"'!$T$7:$T$371"),11),"-")) | M26: =IF($A26="","",IFERROR(SUMIFS(INDIRECT("'"&$A26&"'!$Q$7:$Q$371"),INDIRECT("'"&$A26&"'!$T$7:$T$371"),12),"-")) | N26: =IF($A26="","",SUM(B26:M26))
A27: =$A13 | B27: =IF($A27="","",IFERROR(SUMIFS(INDIRECT("'"&$A27&"'!$Q$7:$Q$371"),INDIRECT("'"&$A27&"'!$T$7:$T$371"),1),"-")) | C27: =IF($A27="","",IFERROR(SUMIFS(INDIRECT("'"&$A27&"'!$Q$7:$Q$371"),INDIRECT("'"&$A27&"'!$T$7:$T$371"),2),"-")) | D27: =IF($A27="","",IFERROR(SUMIFS(INDIRECT("'"&$A27&"'!$Q$7:$Q$371"),INDIRECT("'"&$A27&"'!$T$7:$T$371"),3),"-")) | E27: =IF($A27="","",IFERROR(SUMIFS(INDIRECT("'"&$A27&"'!$Q$7:$Q$371"),INDIRECT("'"&$A27&"'!$T$7:$T$371"),4),"-")) | F27: =IF($A27="","",IFERROR(SUMIFS(INDIRECT("'"&$A27&"'!$Q$7:$Q$371"),INDIRECT("'"&$A27&"'!$T$7:$T$371"),5),"-")) | G27: =IF($A27="","",IFERROR(SUMIFS(INDIRECT("'"&$A27&"'!$Q$7:$Q$371"),INDIRECT("'"&$A27&"'!$T$7:$T$371"),6),"-")) | H27: =IF($A27="","",IFERROR(SUMIFS(INDIRECT("'"&$A27&"'!$Q$7:$Q$371"),INDIRECT("'"&$A27&"'!$T$7:$T$371"),7),"-")) | I27: =IF($A27="","",IFERROR(SUMIFS(INDIRECT("'"&$A27&"'!$Q$7:$Q$371"),INDIRECT("'"&$A27&"'!$T$7:$T$371"),8),"-")) | J27: =IF($A27="","",IFERROR(SUMIFS(INDIRECT("'"&$A27&"'!$Q$7:$Q$371"),INDIRECT("'"&$A27&"'!$T$7:$T$371"),9),"-")) | K27: =IF($A27="","",IFERROR(SUMIFS(INDIRECT("'"&$A27&"'!$Q$7:$Q$371"),INDIRECT("'"&$A27&"'!$T$7:$T$371"),10),"-")) | L27: =IF($A27="","",IFERROR(SUMIFS(INDIRECT("'"&$A27&"'!$Q$7:$Q$371"),INDIRECT("'"&$A27&"'!$T$7:$T$371"),11),"-")) | M27: =IF($A27="","",IFERROR(SUMIFS(INDIRECT("'"&$A27&"'!$Q$7:$Q$371"),INDIRECT("'"&$A27&"'!$T$7:$T$371"),12),"-")) | N27: =IF($A27="","",SUM(B27:M27))
A28: =$A14 | B28: =IF($A28="","",IFERROR(SUMIFS(INDIRECT("'"&$A28&"'!$Q$7:$Q$371"),INDIRECT("'"&$A28&"'!$T$7:$T$371"),1),"-")) | C28: =IF($A28="","",IFERROR(SUMIFS(INDIRECT("'"&$A28&"'!$Q$7:$Q$371"),INDIRECT("'"&$A28&"'!$T$7:$T$371"),2),"-")) | D28: =IF($A28="","",IFERROR(SUMIFS(INDIRECT("'"&$A28&"'!$Q$7:$Q$371"),INDIRECT("'"&$A28&"'!$T$7:$T$371"),3),"-")) | E28: =IF($A28="","",IFERROR(SUMIFS(INDIRECT("'"&$A28&"'!$Q$7:$Q$371"),INDIRECT("'"&$A28&"'!$T$7:$T$371"),4),"-")) | F28: =IF($A28="","",IFERROR(SUMIFS(INDIRECT("'"&$A28&"'!$Q$7:$Q$371"),INDIRECT("'"&$A28&"'!$T$7:$T$371"),5),"-")) | G28: =IF($A28="","",IFERROR(SUMIFS(INDIRECT("'"&$A28&"'!$Q$7:$Q$371"),INDIRECT("'"&$A28&"'!$T$7:$T$371"),6),"-")) | H28: =IF($A28="","",IFERROR(SUMIFS(INDIRECT("'"&$A28&"'!$Q$7:$Q$371"),INDIRECT("'"&$A28&"'!$T$7:$T$371"),7),"-")) | I28: =IF($A28="","",IFERROR(SUMIFS(INDIRECT("'"&$A28&"'!$Q$7:$Q$371"),INDIRECT("'"&$A28&"'!$T$7:$T$371"),8),"-")) | J28: =IF($A28="","",IFERROR(SUMIFS(INDIRECT("'"&$A28&"'!$Q$7:$Q$371"),INDIRECT("'"&$A28&"'!$T$7:$T$371"),9),"-")) | K28: =IF($A28="","",IFERROR(SUMIFS(INDIRECT("'"&$A28&"'!$Q$7:$Q$371"),INDIRECT("'"&$A28&"'!$T$7:$T$371"),10),"-")) | L28: =IF($A28="","",IFERROR(SUMIFS(INDIRECT("'"&$A28&"'!$Q$7:$Q$371"),INDIRECT("'"&$A28&"'!$T$7:$T$371"),11),"-")) | M28: =IF($A28="","",IFERROR(SUMIFS(INDIRECT("'"&$A28&"'!$Q$7:$Q$371"),INDIRECT("'"&$A28&"'!$T$7:$T$371"),12),"-")) | N28: =IF($A28="","",SUM(B28:M28))
A29: =$A15 | B29: =IF($A29="","",IFERROR(SUMIFS(INDIRECT("'"&$A29&"'!$Q$7:$Q$371"),INDIRECT("'"&$A29&"'!$T$7:$T$371"),1),"-")) | C29: =IF($A29="","",IFERROR(SUMIFS(INDIRECT("'"&$A29&"'!$Q$7:$Q$371"),INDIRECT("'"&$A29&"'!$T$7:$T$371"),2),"-")) | D29: =IF($A29="","",IFERROR(SUMIFS(INDIRECT("'"&$A29&"'!$Q$7:$Q$371"),INDIRECT("'"&$A29&"'!$T$7:$T$371"),3),"-")) | E29: =IF($A29="","",IFERROR(SUMIFS(INDIRECT("'"&$A29&"'!$Q$7:$Q$371"),INDIRECT("'"&$A29&"'!$T$7:$T$371"),4),"-")) | F29: =IF($A29="","",IFERROR(SUMIFS(INDIRECT("'"&$A29&"'!$Q$7:$Q$371"),INDIRECT("'"&$A29&"'!$T$7:$T$371"),5),"-")) | G29: =IF($A29="","",IFERROR(SUMIFS(INDIRECT("'"&$A29&"'!$Q$7:$Q$371"),INDIRECT("'"&$A29&"'!$T$7:$T$371"),6),"-")) | H29: =IF($A29="","",IFERROR(SUMIFS(INDIRECT("'"&$A29&"'!$Q$7:$Q$371"),INDIRECT("'"&$A29&"'!$T$7:$T$371"),7),"-")) | I29: =IF($A29="","",IFERROR(SUMIFS(INDIRECT("'"&$A29&"'!$Q$7:$Q$371"),INDIRECT("'"&$A29&"'!$T$7:$T$371"),8),"-")) | J29: =IF($A29="","",IFERROR(SUMIFS(INDIRECT("'"&$A29&"'!$Q$7:$Q$371"),INDIRECT("'"&$A29&"'!$T$7:$T$371"),9),"-")) | K29: =IF($A29="","",IFERROR(SUMIFS(INDIRECT("'"&$A29&"'!$Q$7:$Q$371"),INDIRECT("'"&$A29&"'!$T$7:$T$371"),10),"-")) | L29: =IF($A29="","",IFERROR(SUMIFS(INDIRECT("'"&$A29&"'!$Q$7:$Q$371"),INDIRECT("'"&$A29&"'!$T$7:$T$371"),11),"-")) | M29: =IF($A29="","",IFERROR(SUMIFS(INDIRECT("'"&$A29&"'!$Q$7:$Q$371"),INDIRECT("'"&$A29&"'!$T$7:$T$371"),12),"-")) | N29: =IF($A29="","",SUM(B29:M29))

Sheet Tomer Cohen
A1: Attendance 2026 - Tomer Cohen
A2: Fill in only the yellow cells, and only for days that differ from the automatic day.
A3: Vacation days | C3: Vacation hours | E3: Sick leave days | F3: Sick leave hours | H3: Days worked | J3: Worked hours | K3: Entries to check
A4: =SUM(Q7:Q371) -> 0 | C4: =SUM(O7:O371) -> 0 | E4: =SUM(R7:R371) -> 0 | F4: =SUM(P7:P371) -> 0 | H4: =COUNTIF(N7:N371,">0") -> 256 | J4: =SUM(N7:N371) -> 2166 | K4: =COUNTIF(S7:S371,"?*") -> 0
A6: Date | B6: Day | C6: Day type | D6: Holiday | E6: Status (leave empty = automatic) | F6: Start | G6: End | H6: Leave from | I6: Leave to | J6: Notes | K6: Applied status | L6: Applied start | M6: Applied end | N6: Worked hours | O6: Vacation hours | P6: Sick leave hours | Q6: Vacation days | R6: Sick leave days | S6: Check | T6: Month | U6: Working day | V6: Day end | W6: Full day hours
A7: 46023 | B7: =CHOOSE(WEEKDAY(A7),"Sun","Mon","Tue","Wed","Thu","Fri","Sat") -> Thu | C7: =IF(IFERROR(INDEX(Holidays!$D$5:$D$60,MATCH(A7,Holidays!$A$5:$A$60,0)),"")="Holiday","Holiday",IF(WEEKDAY(A7)>=6,"Weekend",IF(IFERROR(INDEX(Holidays!$D$5:$D$60,MATCH(A7,Holidays!$A$5:$A$60,0)),"")="Eve","Eve","Workday"))) -> Workday | D7: =IFERROR(INDEX(Holidays!$C$5:$C$60,MATCH(A7,Holidays!$A$5:$A$60,0)),"") | K7: =IF(E7<>"",E7,IF(U7,"Present",IF(C7="Holiday","Holiday","Weekend"))) -> Present | L7: =IF(OR(K7="Present",K7="Manual Work",K7="Partial Vacation",K7="Partial Sick Leave"),IF(ISNUMBER(F7),F7,IF(AND(K7="Present",U7),Settings!$B$6,"")),"") -> 0.33333333 | M7: =IF(OR(K7="Present",K7="Manual Work",K7="Partial Vacation",K7="Partial Sick Leave"),IF(ISNUMBER(G7),G7,IF(AND(K7="Present",U7),V7,"")),"") -> 0.6875 | N7: =IF(AND(ISNUMBER(L7),ISNUMBER(M7)),MAX(0,(M7-L7)*24),0) -> 8.5 | O7: =IF(NOT(U7),0,IF(K7="Vacation",IF(C7="Eve",Settings!$B$9*Settings!$B$11,W7),IF(K7="Partial Vacation",IF(AND(ISNUMBER(H7),ISNUMBER(I7)),MAX(0,(I7-H7)*24),0),0))) -> 0 | P7: =IF(NOT(U7),0,IF(K7="Sick Leave",W7,IF(K7="Partial Sick Leave",IF(AND(ISNUMBER(H7),ISNUMBER(I7)),MAX(0,(I7-H7)*24),0),0))) -> 0 | Q7: =IF(NOT(U7),0,IF(K7="Vacation",IF(C7="Eve",Settings!$B$11,1),IF(K7="Partial Vacation",O7/Settings!$B$9,0))) -> 0 | R7: =IF(NOT(U7),0,IF(K7="Sick Leave",1,IF(K7="Partial Sick Leave",P7/Settings!$B$9,0))) -> 0 | S7: =IF(AND(OR(E7="Vacation",E7="Sick Leave",E7="Partial Vacation",E7="Partial Sick Leave"),NOT(U7)),"Leave not allowed on this day",IF(AND(E7="Manual Work",OR(NOT(ISNUMBER(F7)),NOT(ISNUMBER(G7)))),"Enter start and end",IF(AND(OR(E7="Partial Vacation",E7="Partial Sick Leave"),OR(NOT(ISNUMBER(H7)),NOT(ISNUMBER(I7)))),"Enter leave from and to",IF(AND(ISNUMBER(F7),ISNUMBER(G7),G7<=F7),"End is before start",IF(AND(ISNUMBER(H7),ISNUMBER(I7),I7<=H7),"Leave end is before start",IF(AND(ISNUMBER(F7),ISNUMBER(G7),ISNUMBER(H7),ISNUMBER(I7),F7<I7,H7<G7),"Work and leave hours overlap",IF(AND(E7<>"",WEEKDAY(A7)=7),"Saturday - administrator only",""))))))) | T7: =MONTH(A7) -> 1 | U7: =OR(C7="Workday",C7="Eve") -> TRUE | V7: =IF(C7="Eve",Settings!$B$8,Settings!$B$7) -> 0.6875 | W7: =IF(U7,(V7-Settings!$B$6)*24,0) -> 8.5
A8: 46024 | B8: =CHOOSE(WEEKDAY(A8),"Sun","Mon","Tue","Wed","Thu","Fri","Sat") -> Fri | C8: =IF(IFERROR(INDEX(Holidays!$D$5:$D$60,MATCH(A8,Holidays!$A$5:$A$60,0)),"")="Holiday","Holiday",IF(WEEKDAY(A8)>=6,"Weekend",IF(IFERROR(INDEX(Holidays!$D$5:$D$60,MATCH(A8,Holidays!$A$5:$A$60,0)),"")="Eve","Eve","Workday"))) -> Weekend | D8: =IFERROR(INDEX(Holidays!$C$5:$C$60,MATCH(A8,Holidays!$A$5:$A$60,0)),"") | K8: =IF(E8<>"",E8,IF(U8,"Present",IF(C8="Holiday","Holiday","Weekend"))) -> Weekend | L8: =IF(OR(K8="Present",K8="Manual Work",K8="Partial Vacation",K8="Partial Sick Leave"),IF(ISNUMBER(F8),F8,IF(AND(K8="Present",U8),Settings!$B$6,"")),"") | M8: =IF(OR(K8="Present",K8="Manual Work",K8="Partial Vacation",K8="Partial Sick Leave"),IF(ISNUMBER(G8),G8,IF(AND(K8="Present",U8),V8,"")),"") | N8: =IF(AND(ISNUMBER(L8),ISNUMBER(M8)),MAX(0,(M8-L8)*24),0) -> 0 | O8: =IF(NOT(U8),0,IF(K8="Vacation",IF(C8="Eve",Settings!$B$9*Settings!$B$11,W8),IF(K8="Partial Vacation",IF(AND(ISNUMBER(H8),ISNUMBER(I8)),MAX(0,(I8-H8)*24),0),0))) -> 0 | P8: =IF(NOT(U8),0,IF(K8="Sick Leave",W8,IF(K8="Partial Sick Leave",IF(AND(ISNUMBER(H8),ISNUMBER(I8)),MAX(0,(I8-H8)*24),0),0))) -> 0 | Q8: =IF(NOT(U8),0,IF(K8="Vacation",IF(C8="Eve",Settings!$B$11,1),IF(K8="Partial Vacation",O8/Settings!$B$9,0))) -> 0 | R8: =IF(NOT(U8),0,IF(K8="Sick Leave",1,IF(K8="Partial Sick Leave",P8/Settings!$B$9,0))) -> 0 | S8: =IF(AND(OR(E8="Vacation",E8="Sick Leave",E8="Partial Vacation",E8="Partial Sick Leave"),NOT(U8)),"Leave not allowed on this day",IF(AND(E8="Manual Work",OR(NOT(ISNUMBER(F8)),NOT(ISNUMBER(G8)))),"Enter start and end",IF(AND(OR(E8="Partial Vacation",E8="Partial Sick Leave"),OR(NOT(ISNUMBER(H8)),NOT(ISNUMBER(I8)))),"Enter leave from and to",IF(AND(ISNUMBER(F8),ISNUMBER(G8),G8<=F8),"End is before start",IF(AND(ISNUMBER(H8),ISNUMBER(I8),I8<=H8),"Leave end is before start",IF(AND(ISNUMBER(F8),ISNUMBER(G8),ISNUMBER(H8),ISNUMBER(I8),F8<I8,H8<G8),"Work and leave hours overlap",IF(AND(E8<>"",WEEKDAY(A8)=7),"Saturday - administrator only",""))))))) | T8: =MONTH(A8) -> 1 | U8: =OR(C8="Workday",C8="Eve") -> FALSE | V8: =IF(C8="Eve",Settings!$B$8,Settings!$B$7) -> 0.6875 | W8: =IF(U8,(V8-Settings!$B$6)*24,0) -> 0
A9: 46025 | B9: =CHOOSE(WEEKDAY(A9),"Sun","Mon","Tue","Wed","Thu","Fri","Sat") -> Sat | C9: =IF(IFERROR(INDEX(Holidays!$D$5:$D$60,MATCH(A9,Holidays!$A$5:$A$60,0)),"")="Holiday","Holiday",IF(WEEKDAY(A9)>=6,"Weekend",IF(IFERROR(INDEX(Holidays!$D$5:$D$60,MATCH(A9,Holidays!$A$5:$A$60,0)),"")="Eve","Eve","Workday"))) -> Weekend | D9: =IFERROR(INDEX(Holidays!$C$5:$C$60,MATCH(A9,Holidays!$A$5:$A$60,0)),"") | K9: =IF(E9<>"",E9,IF(U9,"Present",IF(C9="Holiday","Holiday","Weekend"))) -> Weekend | L9: =IF(OR(K9="Present",K9="Manual Work",K9="Partial Vacation",K9="Partial Sick Leave"),IF(ISNUMBER(F9),F9,IF(AND(K9="Present",U9),Settings!$B$6,"")),"") | M9: =IF(OR(K9="Present",K9="Manual Work",K9="Partial Vacation",K9="Partial Sick Leave"),IF(ISNUMBER(G9),G9,IF(AND(K9="Present",U9),V9,"")),"") | N9: =IF(AND(ISNUMBER(L9),ISNUMBER(M9)),MAX(0,(M9-L9)*24),0) -> 0 | O9: =IF(NOT(U9),0,IF(K9="Vacation",IF(C9="Eve",Settings!$B$9*Settings!$B$11,W9),IF(K9="Partial Vacation",IF(AND(ISNUMBER(H9),ISNUMBER(I9)),MAX(0,(I9-H9)*24),0),0))) -> 0 | P9: =IF(NOT(U9),0,IF(K9="Sick Leave",W9,IF(K9="Partial Sick Leave",IF(AND(ISNUMBER(H9),ISNUMBER(I9)),MAX(0,(I9-H9)*24),0),0))) -> 0 | Q9: =IF(NOT(U9),0,IF(K9="Vacation",IF(C9="Eve",Settings!$B$11,1),IF(K9="Partial Vacation",O9/Settings!$B$9,0))) -> 0 | R9: =IF(NOT(U9),0,IF(K9="Sick Leave",1,IF(K9="Partial Sick Leave",P9/Settings!$B$9,0))) -> 0 | S9: =IF(AND(OR(E9="Vacation",E9="Sick Leave",E9="Partial Vacation",E9="Partial Sick Leave"),NOT(U9)),"Leave not allowed on this day",IF(AND(E9="Manual Work",OR(NOT(ISNUMBER(F9)),NOT(ISNUMBER(G9)))),"Enter start and end",IF(AND(OR(E9="Partial Vacation",E9="Partial Sick Leave"),OR(NOT(ISNUMBER(H9)),NOT(ISNUMBER(I9)))),"Enter leave from and to",IF(AND(ISNUMBER(F9),ISNUMBER(G9),G9<=F9),"End is before start",IF(AND(ISNUMBER(H9),ISNUMBER(I9),I9<=H9),"Leave end is before start",IF(AND(ISNUMBER(F9),ISNUMBER(G9),ISNUMBER(H9),ISNUMBER(I9),F9<I9,H9<G9),"Work and leave hours overlap",IF(AND(E9<>"",WEEKDAY(A9)=7),"Saturday - administrator only",""))))))) | T9: =MONTH(A9) -> 1 | U9: =OR(C9="Workday",C9="Eve") -> FALSE | V9: =IF(C9="Eve",Settings!$B$8,Settings!$B$7) -> 0.6875 | W9: =IF(U9,(V9-Settings!$B$6)*24,0) -> 0
A10: 46026 | B10: =CHOOSE(WEEKDAY(A10),"Sun","Mon","Tue","Wed","Thu","Fri","Sat") -> Sun | C10: =IF(IFERROR(INDEX(Holidays!$D$5:$D$60,MATCH(A10,Holidays!$A$5:$A$60,0)),"")="Holiday","Holiday",IF(WEEKDAY(A10)>=6,"Weekend",IF(IFERROR(INDEX(Holidays!$D$5:$D$60,MATCH(A10,Holidays!$A$5:$A$60,0)),"")="Eve","Eve","Workday"))) -> Workday | D10: =IFERROR(INDEX(Holidays!$C$5:$C$60,MATCH(A10,Holidays!$A$5:$A$60,0)),"") | K10: =IF(E10<>"",E10,IF(U10,"Present",IF(C10="Holiday","Holiday","Weekend"))) -> Present | L10: =IF(OR(K10="Present",K10="Manual Work",K10="Partial Vacation",K10="Partial Sick Leave"),IF(ISNUMBER(F10),F10,IF(AND(K10="Present",U10),Settings!$B$6,"")),"") -> 0.33333333 | M10: =IF(OR(K10="Present",K10="Manual Work",K10="Partial Vacation",K10="Partial Sick Leave"),IF(ISNUMBER(G10),G10,IF(AND(K10="Present",U10),V10,"")),"") -> 0.6875 | N10: =IF(AND(ISNUMBER(L10),ISNUMBER(M10)),MAX(0,(M10-L10)*24),0) -> 8.5 | O10: =IF(NOT(U10),0,IF(K10="Vacation",IF(C10="Eve",Settings!$B$9*Settings!$B$11,W10),IF(K10="Partial Vacation",IF(AND(ISNUMBER(H10),ISNUMBER(I10)),MAX(0,(I10-H10)*24),0),0))) -> 0 | P10: =IF(NOT(U10),0,IF(K10="Sick Leave",W10,IF(K10="Partial Sick Leave",IF(AND(ISNUMBER(H10),ISNUMBER(I10)),MAX(0,(I10-H10)*24),0),0))) -> 0 | Q10: =IF(NOT(U10),0,IF(K10="Vacation",IF(C10="Eve",Settings!$B$11,1),IF(K10="Partial Vacation",O10/Settings!$B$9,0))) -> 0 | R10: =IF(NOT(U10),0,IF(K10="Sick Leave",1,IF(K10="Partial Sick Leave",P10/Settings!$B$9,0))) -> 0 | S10: =IF(AND(OR(E10="Vacation",E10="Sick Leave",E10="Partial Vacation",E10="Partial Sick Leave"),NOT(U10)),"Leave not allowed on this day",IF(AND(E10="Manual Work",OR(NOT(ISNUMBER(F10)),NOT(ISNUMBER(G10)))),"Enter start and end",IF(AND(OR(E10="Partial Vacation",E10="Partial Sick Leave"),OR(NOT(ISNUMBER(H10)),NOT(ISNUMBER(I10)))),"Enter leave from and to",IF(AND(ISNUMBER(F10),ISNUMBER(G10),G10<=F10),"End is before start",IF(AND(ISNUMBER(H10),ISNUMBER(I10),I10<=H10),"Leave end is before start",IF(AND(ISNUMBER(F10),ISNUMBER(G10),ISNUMBER(H10),ISNUMBER(I10),F10<I10,H10<G10),"Work and leave hours overlap",IF(AND(E10<>"",WEEKDAY(A10)=7),"Saturday - administrator only",""))))))) | T10: =MONTH(A10) -> 1 | U10: =OR(C10="Workday",C10="Eve") -> TRUE | V10: =IF(C10="Eve",Settings!$B$8,Settings!$B$7) -> 0.6875 | W10: =IF(U10,(V10-Settings!$B$6)*24,0) -> 8.5
A11: 46027 | B11: =CHOOSE(WEEKDAY(A11),"Sun","Mon","Tue","Wed","Thu","Fri","Sat") -> Mon | C11: =IF(IFERROR(INDEX(Holidays!$D$5:$D$60,MATCH(A11,Holidays!$A$5:$A$60,0)),"")="Holiday","Holiday",IF(WEEKDAY(A11)>=6,"Weekend",IF(IFERROR(INDEX(Holidays!$D$5:$D$60,MATCH(A11,Holidays!$A$5:$A$60,0)),"")="Eve","Eve","Workday"))) -> Workday | D11: =IFERROR(INDEX(Holidays!$C$5:$C$60,MATCH(A11,Holidays!$A$5:$A$60,0)),"") | K11: =IF(E11<>"",E11,IF(U11,"Present",IF(C11="Holiday","Holiday","Weekend"))) -> Present | L11: =IF(OR(K11="Present",K11="Manual Work",K11="Partial Vacation",K11="Partial Sick Leave"),IF(ISNUMBER(F11),F11,IF(AND(K11="Present",U11),Settings!$B$6,"")),"") -> 0.33333333 | M11: =IF(OR(K11="Present",K11="Manual Work",K11="Partial Vacation",K11="Partial Sick Leave"),IF(ISNUMBER(G11),G11,IF(AND(K11="Present",U11),V11,"")),"") -> 0.6875 | N11: =IF(AND(ISNUMBER(L11),ISNUMBER(M11)),MAX(0,(M11-L11)*24),0) -> 8.5 | O11: =IF(NOT(U11),0,IF(K11="Vacation",IF(C11="Eve",Settings!$B$9*Settings!$B$11,W11),IF(K11="Partial Vacation",IF(AND(ISNUMBER(H11),ISNUMBER(I11)),MAX(0,(I11-H11)*24),0),0))) -> 0 | P11: =IF(NOT(U11),0,IF(K11="Sick Leave",W11,IF(K11="Partial Sick Leave",IF(AND(ISNUMBER(H11),ISNUMBER(I11)),MAX(0,(I11-H11)*24),0),0))) -> 0 | Q11: =IF(NOT(U11),0,IF(K11="Vacation",IF(C11="Eve",Settings!$B$11,1),IF(K11="Partial Vacation",O11/Settings!$B$9,0))) -> 0 | R11: =IF(NOT(U11),0,IF(K11="Sick Leave",1,IF(K11="Partial Sick Leave",P11/Settings!$B$9,0))) -> 0 | S11: =IF(AND(OR(E11="Vacation",E11="Sick Leave",E11="Partial Vacation",E11="Partial Sick Leave"),NOT(U11)),"Leave not allowed on this day",IF(AND(E11="Manual Work",OR(NOT(ISNUMBER(F11)),NOT(ISNUMBER(G11)))),"Enter start and end",IF(AND(OR(E11="Partial Vacation",E11="Partial Sick Leave"),OR(NOT(ISNUMBER(H11)),NOT(ISNUMBER(I11)))),"Enter leave from and to",IF(AND(ISNUMBER(F11),ISNUMBER(G11),G11<=F11),"End is before start",IF(AND(ISNUMBER(H11),ISNUMBER(I11),I11<=H11),"Leave end is before start",IF(AND(ISNUMBER(F11),ISNUMBER(G11),ISNUMBER(H11),ISNUMBER(I11),F11<I11,H11<G11),"Work and leave hours overlap",IF(AND(E11<>"",WEEKDAY(A11)=7),"Saturday - administrator only",""))))))) | T11: =MONTH(A11) -> 1 | U11: =OR(C11="Workday",C11="Eve") -> TRUE | V11: =IF(C11="Eve",Settings!$B$8,Settings!$B$7) -> 0.6875 | W11: =IF(U11,(V11-Settings!$B$6)*24,0) -> 8.5
A12: 46028 | B12: =CHOOSE(WEEKDAY(A12),"Sun","Mon","Tue","Wed","Thu","Fri","Sat") -> Tue | C12: =IF(IFERROR(INDEX(Holidays!$D$5:$D$60,MATCH(A12,Holidays!$A$5:$A$60,0)),"")="Holiday","Holiday",IF(WEEKDAY(A12)>=6,"Weekend",IF(IFERROR(INDEX(Holidays!$D$5:$D$60,MATCH(A12,Holidays!$A$5:$A$60,0)),"")="Eve","Eve","Workday"))) -> Workday | D12: =IFERROR(INDEX(Holidays!$C$5:$C$60,MATCH(A12,Holidays!$A$5:$A$60,0)),"") | K12: =IF(E12<>"",E12,IF(U12,"Present",IF(C12="Holiday","Holiday","Weekend"))) -> Present | L12: =IF(OR(K12="Present",K12="Manual Work",K12="Partial Vacation",K12="Partial Sick Leave"),IF(ISNUMBER(F12),F12,IF(AND(K12="Present",U12),Settings!$B$6,"")),"") -> 0.33333333 | M12: =IF(OR(K12="Present",K12="Manual Work",K12="Partial Vacation",K12="Partial Sick Leave"),IF(ISNUMBER(G12),G12,IF(AND(K12="Present",U12),V12,"")),"") -> 0.6875 | N12: =IF(AND(ISNUMBER(L12),ISNUMBER(M12)),MAX(0,(M12-L12)*24),0) -> 8.5 | O12: =IF(NOT(U12),0,IF(K12="Vacation",IF(C12="Eve",Settings!$B$9*Settings!$B$11,W12),IF(K12="Partial Vacation",IF(AND(ISNUMBER(H12),ISNUMBER(I12)),MAX(0,(I12-H12)*24),0),0))) -> 0 | P12: =IF(NOT(U12),0,IF(K12="Sick Leave",W12,IF(K12="Partial Sick Leave",IF(AND(ISNUMBER(H12),ISNUMBER(I12)),MAX(0,(I12-H12)*24),0),0))) -> 0 | Q12: =IF(NOT(U12),0,IF(K12="Vacation",IF(C12="Eve",Settings!$B$11,1),IF(K12="Partial Vacation",O12/Settings!$B$9,0))) -> 0 | R12: =IF(NOT(U12),0,IF(K12="Sick Leave",1,IF(K12="Partial Sick Leave",P12/Settings!$B$9,0))) -> 0 | S12: =IF(AND(OR(E12="Vacation",E12="Sick Leave",E12="Partial Vacation",E12="Partial Sick Leave"),NOT(U12)),"Leave not allowed on this day",IF(AND(E12="Manual Work",OR(NOT(ISNUMBER(F12)),NOT(ISNUMBER(G12)))),"Enter start and end",IF(AND(OR(E12="Partial Vacation",E12="Partial Sick Leave"),OR(NOT(ISNUMBER(H12)),NOT(ISNUMBER(I12)))),"Enter leave from and to",IF(AND(ISNUMBER(F12),ISNUMBER(G12),G12<=F12),"End is before start",IF(AND(ISNUMBER(H12),ISNUMBER(I12),I12<=H12),"Leave end is before start",IF(AND(ISNUMBER(F12),ISNUMBER(G12),ISNUMBER(H12),ISNUMBER(I12),F12<I12,H12<G12),"Work and leave hours overlap",IF(AND(E12<>"",WEEKDAY(A12)=7),"Saturday - administrator only",""))))))) | T12: =MONTH(A12) -> 1 | U12: =OR(C12="Workday",C12="Eve") -> TRUE | V12: =IF(C12="Eve",Settings!$B$8,Settings!$B$7) -> 0.6875 | W12: =IF(U12,(V12-Settings!$B$6)*24,0) -> 8.5
A13: 46029 | B13: =CHOOSE(WEEKDAY(A13),"Sun","Mon","Tue","Wed","Thu","Fri","Sat") -> Wed | C13: =IF(IFERROR(INDEX(Holidays!$D$5:$D$60,MATCH(A13,Holidays!$A$5:$A$60,0)),"")="Holiday","Holiday",IF(WEEKDAY(A13)>=6,"Weekend",IF(IFERROR(INDEX(Holidays!$D$5:$D$60,MATCH(A13,Holidays!$A$5:$A$60,0)),"")="Eve","Eve","Workday"))) -> Workday | D13: =IFERROR(INDEX(Holidays!$C$5:$C$60,MATCH(A13,Holidays!$A$5:$A$60,0)),"") | K13: =IF(E13<>"",E13,IF(U13,"Present",IF(C13="Holiday","Holiday","Weekend"))) -> Present | L13: =IF(OR(K13="Present",K13="Manual Work",K13="Partial Vacation",K13="Partial Sick Leave"),IF(ISNUMBER(F13),F13,IF(AND(K13="Present",U13),Settings!$B$6,"")),"") -> 0.33333333 | M13: =IF(OR(K13="Present",K13="Manual Work",K13="Partial Vacation",K13="Partial Sick Leave"),IF(ISNUMBER(G13),G13,IF(AND(K13="Present",U13),V13,"")),"") -> 0.6875 | N13: =IF(AND(ISNUMBER(L13),ISNUMBER(M13)),MAX(0,(M13-L13)*24),0) -> 8.5 | O13: =IF(NOT(U13),0,IF(K13="Vacation",IF(C13="Eve",Settings!$B$9*Settings!$B$11,W13),IF(K13="Partial Vacation",IF(AND(ISNUMBER(H13),ISNUMBER(I13)),MAX(0,(I13-H13)*24),0),0))) -> 0 | P13: =IF(NOT(U13),0,IF(K13="Sick Leave",W13,IF(K13="Partial Sick Leave",IF(AND(ISNUMBER(H13),ISNUMBER(I13)),MAX(0,(I13-H13)*24),0),0))) -> 0 | Q13: =IF(NOT(U13),0,IF(K13="Vacation",IF(C13="Eve",Settings!$B$11,1),IF(K13="Partial Vacation",O13/Settings!$B$9,0))) -> 0 | R13: =IF(NOT(U13),0,IF(K13="Sick Leave",1,IF(K13="Partial Sick Leave",P13/Settings!$B$9,0))) -> 0 | S13: =IF(AND(OR(E13="Vacation",E13="Sick Leave",E13="Partial Vacation",E13="Partial Sick Leave"),NOT(U13)),"Leave not allowed on this day",IF(AND(E13="Manual Work",OR(NOT(ISNUMBER(F13)),NOT(ISNUMBER(G13)))),"Enter start and end",IF(AND(OR(E13="Partial Vacation",E13="Partial Sick Leave"),OR(NOT(ISNUMBER(H13)),NOT(ISNUMBER(I13)))),"Enter leave from and to",IF(AND(ISNUMBER(F13),ISNUMBER(G13),G13<=F13),"End is before start",IF(AND(ISNUMBER(H13),ISNUMBER(I13),I13<=H13),"Leave end is before start",IF(AND(ISNUMBER(F13),ISNUMBER(G13),ISNUMBER(H13),ISNUMBER(I13),F13<I13,H13<G13),"Work and leave hours overlap",IF(AND(E13<>"",WEEKDAY(A13)=7),"Saturday - administrator only",""))))))) | T13: =MONTH(A13) -> 1 | U13: =OR(C13="Workday",C13="Eve") -> TRUE | V13: =IF(C13="Eve",Settings!$B$8,Settings!$B$7) -> 0.6875 | W13: =IF(U13,(V13-Settings!$B$6)*24,0) -> 8.5
A14: 46030 | B14: =CHOOSE(WEEKDAY(A14),"Sun","Mon","Tue","Wed","Thu","Fri","Sat") -> Thu | C14: =IF(IFERROR(INDEX(Holidays!$D$5:$D$60,MATCH(A14,Holidays!$A$5:$A$60,0)),"")="Holiday","Holiday",IF(WEEKDAY(A14)>=6,"Weekend",IF(IFERROR(INDEX(Holidays!$D$5:$D$60,MATCH(A14,Holidays!$A$5:$A$60,0)),"")="Eve","Eve","Workday"))) -> Workday | D14: =IFERROR(INDEX(Holidays!$C$5:$C$60,MATCH(A14,Holidays!$A$5:$A$60,0)),"") | K14: =IF(E14<>"",E14,IF(U14,"Present",IF(C14="Holiday","Holiday","Weekend"))) -> Present | L14: =IF(OR(K14="Present",K14="Manual Work",K14="Partial Vacation",K14="Partial Sick Leave"),IF(ISNUMBER(F14),F14,IF(AND(K14="Present",U14),Settings!$B$6,"")),"") -> 0.33333333 | M14: =IF(OR(K14="Present",K14="Manual Work",K14="Partial Vacation",K14="Partial Sick Leave"),IF(ISNUMBER(G14),G14,IF(AND(K14="Present",U14),V14,"")),"") -> 0.6875 | N14: =IF(AND(ISNUMBER(L14),ISNUMBER(M14)),MAX(0,(M14-L14)*24),0) -> 8.5 | O14: =IF(NOT(U14),0,IF(K14="Vacation",IF(C14="Eve",Settings!$B$9*Settings!$B$11,W14),IF(K14="Partial Vacation",IF(AND(ISNUMBER(H14),ISNUMBER(I14)),MAX(0,(I14-H14)*24),0),0))) -> 0 | P14: =IF(NOT(U14),0,IF(K14="Sick Leave",W14,IF(K14="Partial Sick Leave",IF(AND(ISNUMBER(H14),ISNUMBER(I14)),MAX(0,(I14-H14)*24),0),0))) -> 0 | Q14: =IF(NOT(U14),0,IF(K14="Vacation",IF(C14="Eve",Settings!$B$11,1),IF(K14="Partial Vacation",O14/Settings!$B$9,0))) -> 0 | R14: =IF(NOT(U14),0,IF(K14="Sick Leave",1,IF(K14="Partial Sick Leave",P14/Settings!$B$9,0))) -> 0 | S14: =IF(AND(OR(E14="Vacation",E14="Sick Leave",E14="Partial Vacation",E14="Partial Sick Leave"),NOT(U14)),"Leave not allowed on this day",IF(AND(E14="Manual Work",OR(NOT(ISNUMBER(F14)),NOT(ISNUMBER(G14)))),"Enter start and end",IF(AND(OR(E14="Partial Vacation",E14="Partial Sick Leave"),OR(NOT(ISNUMBER(H14)),NOT(ISNUMBER(I14)))),"Enter leave from and to",IF(AND(ISNUMBER(F14),ISNUMBER(G14),G14<=F14),"End is before start",IF(AND(ISNUMBER(H14),ISNUMBER(I14),I14<=H14),"Leave end is before start",IF(AND(ISNUMBER(F14),ISNUMBER(G14),ISNUMBER(H14),ISNUMBER(I14),F14<I14,H14<G14),"Work and leave hours overlap",IF(AND(E14<>"",WEEKDAY(A14)=7),"Saturday - administrator only",""))))))) | T14: =MONTH(A14) -> 1 | U14: =OR(C14="Workday",C14="Eve") -> TRUE | V14: =IF(C14="Eve",Settings!$B$8,Settings!$B$7) -> 0.6875 | W14: =IF(U14,(V14-Settings!$B$6)*24,0) -> 8.5
A15: 46031 | B15: =CHOOSE(WEEKDAY(A15),"Sun","Mon","Tue","Wed","Thu","Fri","Sat") -> Fri | C15: =IF(IFERROR(INDEX(Holidays!$D$5:$D$60,MATCH(A15,Holidays!$A$5:$A$60,0)),"")="Holiday","Holiday",IF(WEEKDAY(A15)>=6,"Weekend",IF(IFERROR(INDEX(Holidays!$D$5:$D$60,MATCH(A15,Holidays!$A$5:$A$60,0)),"")="Eve","Eve","Workday"))) -> Weekend | D15: =IFERROR(INDEX(Holidays!$C$5:$C$60,MATCH(A15,Holidays!$A$5:$A$60,0)),"") | K15: =IF(E15<>"",E15,IF(U15,"Present",IF(C15="Holiday","Holiday","Weekend"))) -> Weekend | L15: =IF(OR(K15="Present",K15="Manual Work",K15="Partial Vacation",K15="Partial Sick Leave"),IF(ISNUMBER(F15),F15,IF(AND(K15="Present",U15),Settings!$B$6,"")),"") | M15: =IF(OR(K15="Present",K15="Manual Work",K15="Partial Vacation",K15="Partial Sick Leave"),IF(ISNUMBER(G15),G15,IF(AND(K15="Present",U15),V15,"")),"") | N15: =IF(AND(ISNUMBER(L15),ISNUMBER(M15)),MAX(0,(M15-L15)*24),0) -> 0 | O15: =IF(NOT(U15),0,IF(K15="Vacation",IF(C15="Eve",Settings!$B$9*Settings!$B$11,W15),IF(K15="Partial Vacation",IF(AND(ISNUMBER(H15),ISNUMBER(I15)),MAX(0,(I15-H15)*24),0),0))) -> 0 | P15: =IF(NOT(U15),0,IF(K15="Sick Leave",W15,IF(K15="Partial Sick Leave",IF(AND(ISNUMBER(H15),ISNUMBER(I15)),MAX(0,(I15-H15)*24),0),0))) -> 0 | Q15: =IF(NOT(U15),0,IF(K15="Vacation",IF(C15="Eve",Settings!$B$11,1),IF(K15="Partial Vacation",O15/Settings!$B$9,0))) -> 0 | R15: =IF(NOT(U15),0,IF(K15="Sick Leave",1,IF(K15="Partial Sick Leave",P15/Settings!$B$9,0))) -> 0 | S15: =IF(AND(OR(E15="Vacation",E15="Sick Leave",E15="Partial Vacation",E15="Partial Sick Leave"),NOT(U15)),"Leave not allowed on this day",IF(AND(E15="Manual Work",OR(NOT(ISNUMBER(F15)),NOT(ISNUMBER(G15)))),"Enter start and end",IF(AND(OR(E15="Partial Vacation",E15="Partial Sick Leave"),OR(NOT(ISNUMBER(H15)),NOT(ISNUMBER(I15)))),"Enter leave from and to",IF(AND(ISNUMBER(F15),ISNUMBER(G15),G15<=F15),"End is before start",IF(AND(ISNUMBER(H15),ISNUMBER(I15),I15<=H15),"Leave end is before start",IF(AND(ISNUMBER(F15),ISNUMBER(G15),ISNUMBER(H15),ISNUMBER(I15),F15<I15,H15<G15),"Work and leave hours overlap",IF(AND(E15<>"",WEEKDAY(A15)=7),"Saturday - administrator only",""))))))) | T15: =MONTH(A15) -> 1 | U15: =OR(C15="Workday",C15="Eve") -> FALSE | V15: =IF(C15="Eve",Settings!$B$8,Settings!$B$7) -> 0.6875 | W15: =IF(U15,(V15-Settings!$B$6)*24,0) -> 0
A16: 46032 | B16: =CHOOSE(WEEKDAY(A16),"Sun","Mon","Tue","Wed","Thu","Fri","Sat") -> Sat | C16: =IF(IFERROR(INDEX(Holidays!$D$5:$D$60,MATCH(A16,Holidays!$A$5:$A$60,0)),"")="Holiday","Holiday",IF(WEEKDAY(A16)>=6,"Weekend",IF(IFERROR(INDEX(Holidays!$D$5:$D$60,MATCH(A16,Holidays!$A$5:$A$60,0)),"")="Eve","Eve","Workday"))) -> Weekend | D16: =IFERROR(INDEX(Holidays!$C$5:$C$60,MATCH(A16,Holidays!$A$5:$A$60,0)),"") | K16: =IF(E16<>"",E16,IF(U16,"Present",IF(C16="Holiday","Holiday","Weekend"))) -> Weekend | L16: =IF(OR(K16="Present",K16="Manual Work",K16="Partial Vacation",K16="Partial Sick Leave"),IF(ISNUMBER(F16),F16,IF(AND(K16="Present",U16),Settings!$B$6,"")),"") | M16: =IF(OR(K16="Present",K16="Manual Work",K16="Partial Vacation",K16="Partial Sick Leave"),IF(ISNUMBER(G16),G16,IF(AND(K16="Present",U16),V16,"")),"") | N16: =IF(AND(ISNUMBER(L16),ISNUMBER(M16)),MAX(0,(M16-L16)*24),0) -> 0 | O16: =IF(NOT(U16),0,IF(K16="Vacation",IF(C16="Eve",Settings!$B$9*Settings!$B$11,W16),IF(K16="Partial Vacation",IF(AND(ISNUMBER(H16),ISNUMBER(I16)),MAX(0,(I16-H16)*24),0),0))) -> 0 | P16: =IF(NOT(U16),0,IF(K16="Sick Leave",W16,IF(K16="Partial Sick Leave",IF(AND(ISNUMBER(H16),ISNUMBER(I16)),MAX(0,(I16-H16)*24),0),0))) -> 0 | Q16: =IF(NOT(U16),0,IF(K16="Vacation",IF(C16="Eve",Settings!$B$11,1),IF(K16="Partial Vacation",O16/Settings!$B$9,0))) -> 0 | R16: =IF(NOT(U16),0,IF(K16="Sick Leave",1,IF(K16="Partial Sick Leave",P16/Settings!$B$9,0))) -> 0 | S16: =IF(AND(OR(E16="Vacation",E16="Sick Leave",E16="Partial Vacation",E16="Partial Sick Leave"),NOT(U16)),"Leave not allowed on this day",IF(AND(E16="Manual Work",OR(NOT(ISNUMBER(F16)),NOT(ISNUMBER(G16)))),"Enter start and end",IF(AND(OR(E16="Partial Vacation",E16="Partial Sick Leave"),OR(NOT(ISNUMBER(H16)),NOT(ISNUMBER(I16)))),"Enter leave from and to",IF(AND(ISNUMBER(F16),ISNUMBER(G16),G16<=F16),"End is before start",IF(AND(ISNUMBER(H16),ISNUMBER(I16),I16<=H16),"Leave end is before start",IF(AND(ISNUMBER(F16),ISNUMBER(G16),ISNUMBER(H16),ISNUMBER(I16),F16<I16,H16<G16),"Work and leave hours overlap",IF(AND(E16<>"",WEEKDAY(A16)=7),"Saturday - administrator only",""))))))) | T16: =MONTH(A16) -> 1 | U16: =OR(C16="Workday",C16="Eve") -> FALSE | V16: =IF(C16="Eve",Settings!$B$8,Settings!$B$7) -> 0.6875 | W16: =IF(U16,(V16-Settings!$B$6)*24,0) -> 0
A17: 46033 | B17: =CHOOSE(WEEKDAY(A17),"Sun","Mon","Tue","Wed","Thu","Fri","Sat") -> Sun | C17: =IF(IFERROR(INDEX(Holidays!$D$5:$D$60,MATCH(A17,Holidays!$A$5:$A$60,0)),"")="Holiday","Holiday",IF(WEEKDAY(A17)>=6,"Weekend",IF(IFERROR(INDEX(Holidays!$D$5:$D$60,MATCH(A17,Holidays!$A$5:$A$60,0)),"")="Eve","Eve","Workday"))) -> Workday | D17: =IFERROR(INDEX(Holidays!$C$5:$C$60,MATCH(A17,Holidays!$A$5:$A$60,0)),"") | K17: =IF(E17<>"",E17,IF(U17,"Present",IF(C17="Holiday","Holiday","Weekend"))) -> Present | L17: =IF(OR(K17="Present",K17="Manual Work",K17="Partial Vacation",K17="Partial Sick Leave"),IF(ISNUMBER(F17),F17,IF(AND(K17="Present",U17),Settings!$B$6,"")),"") -> 0.33333333 | M17: =IF(OR(K17="Present",K17="Manual Work",K17="Partial Vacation",K17="Partial Sick Leave"),IF(ISNUMBER(G17),G17,IF(AND(K17="Present",U17),V17,"")),"") -> 0.6875 | N17: =IF(AND(ISNUMBER(L17),ISNUMBER(M17)),MAX(0,(M17-L17)*24),0) -> 8.5 | O17: =IF(NOT(U17),0,IF(K17="Vacation",IF(C17="Eve",Settings!$B$9*Settings!$B$11,W17),IF(K17="Partial Vacation",IF(AND(ISNUMBER(H17),ISNUMBER(I17)),MAX(0,(I17-H17)*24),0),0))) -> 0 | P17: =IF(NOT(U17),0,IF(K17="Sick Leave",W17,IF(K17="Partial Sick Leave",IF(AND(ISNUMBER(H17),ISNUMBER(I17)),MAX(0,(I17-H17)*24),0),0))) -> 0 | Q17: =IF(NOT(U17),0,IF(K17="Vacation",IF(C17="Eve",Settings!$B$11,1),IF(K17="Partial Vacation",O17/Settings!$B$9,0))) -> 0 | R17: =IF(NOT(U17),0,IF(K17="Sick Leave",1,IF(K17="Partial Sick Leave",P17/Settings!$B$9,0))) -> 0 | S17: =IF(AND(OR(E17="Vacation",E17="Sick Leave",E17="Partial Vacation",E17="Partial Sick Leave"),NOT(U17)),"Leave not allowed on this day",IF(AND(E17="Manual Work",OR(NOT(ISNUMBER(F17)),NOT(ISNUMBER(G17)))),"Enter start and end",IF(AND(OR(E17="Partial Vacation",E17="Partial Sick Leave"),OR(NOT(ISNUMBER(H17)),NOT(ISNUMBER(I17)))),"Enter leave from and to",IF(AND(ISNUMBER(F17),ISNUMBER(G17),G17<=F17),"End is before start",IF(AND(ISNUMBER(H17),ISNUMBER(I17),I17<=H17),"Leave end is before start",IF(AND(ISNUMBER(F17),ISNUMBER(G17),ISNUMBER(H17),ISNUMBER(I17),F17<I17,H17<G17),"Work and leave hours overlap",IF(AND(E17<>"",WEEKDAY(A17)=7),"Saturday - administrator only",""))))))) | T17: =MONTH(A17) -> 1 | U17: =OR(C17="Workday",C17="Eve") -> TRUE | V17: =IF(C17="Eve",Settings!$B$8,Settings!$B$7) -> 0.6875 | W17: =IF(U17,(V17-Settings!$B$6)*24,0) -> 8.5
A18: 46034 | B18: =CHOOSE(WEEKDAY(A18),"Sun","Mon","Tue","Wed","Thu","Fri","Sat") -> Mon | C18: =IF(IFERROR(INDEX(Holidays!$D$5:$D$60,MATCH(A18,Holidays!$A$5:$A$60,0)),"")="Holiday","Holiday",IF(WEEKDAY(A18)>=6,"Weekend",IF(IFERROR(INDEX(Holidays!$D$5:$D$60,MATCH(A18,Holidays!$A$5:$A$60,0)),"")="Eve","Eve","Workday"))) -> Workday | D18: =IFERROR(INDEX(Holidays!$C$5:$C$60,MATCH(A18,Holidays!$A$5:$A$60,0)),"") | K18: =IF(E18<>"",E18,IF(U18,"Present",IF(C18="Holiday","Holiday","Weekend"))) -> Present | L18: =IF(OR(K18="Present",K18="Manual Work",K18="Partial Vacation",K18="Partial Sick Leave"),IF(ISNUMBER(F18),F18,IF(AND(K18="Present",U18),Settings!$B$6,"")),"") -> 0.33333333 | M18: =IF(OR(K18="Present",K18="Manual Work",K18="Partial Vacation",K18="Partial Sick Leave"),IF(ISNUMBER(G18),G18,IF(AND(K18="Present",U18),V18,"")),"") -> 0.6875 | N18: =IF(AND(ISNUMBER(L18),ISNUMBER(M18)),MAX(0,(M18-L18)*24),0) -> 8.5 | O18: =IF(NOT(U18),0,IF(K18="Vacation",IF(C18="Eve",Settings!$B$9*Settings!$B$11,W18),IF(K18="Partial Vacation",IF(AND(ISNUMBER(H18),ISNUMBER(I18)),MAX(0,(I18-H18)*24),0),0))) -> 0 | P18: =IF(NOT(U18),0,IF(K18="Sick Leave",W18,IF(K18="Partial Sick Leave",IF(AND(ISNUMBER(H18),ISNUMBER(I18)),MAX(0,(I18-H18)*24),0),0))) -> 0 | Q18: =IF(NOT(U18),0,IF(K18="Vacation",IF(C18="Eve",Settings!$B$11,1),IF(K18="Partial Vacation",O18/Settings!$B$9,0))) -> 0 | R18: =IF(NOT(U18),0,IF(K18="Sick Leave",1,IF(K18="Partial Sick Leave",P18/Settings!$B$9,0))) -> 0 | S18: =IF(AND(OR(E18="Vacation",E18="Sick Leave",E18="Partial Vacation",E18="Partial Sick Leave"),NOT(U18)),"Leave not allowed on this day",IF(AND(E18="Manual Work",OR(NOT(ISNUMBER(F18)),NOT(ISNUMBER(G18)))),"Enter start and end",IF(AND(OR(E18="Partial Vacation",E18="Partial Sick Leave"),OR(NOT(ISNUMBER(H18)),NOT(ISNUMBER(I18)))),"Enter leave from and to",IF(AND(ISNUMBER(F18),ISNUMBER(G18),G18<=F18),"End is before start",IF(AND(ISNUMBER(H18),ISNUMBER(I18),I18<=H18),"Leave end is before start",IF(AND(ISNUMBER(F18),ISNUMBER(G18),ISNUMBER(H18),ISNUMBER(I18),F18<I18,H18<G18),"Work and leave hours overlap",IF(AND(E18<>"",WEEKDAY(A18)=7),"Saturday - administrator only",""))))))) | T18: =MONTH(A18) -> 1 | U18: =OR(C18="Workday",C18="Eve") -> TRUE | V18: =IF(C18="Eve",Settings!$B$8,Settings!$B$7) -> 0.6875 | W18: =IF(U18,(V18-Settings!$B$6)*24,0) -> 8.5
... A371: 46387 | B371: =CHOOSE(WEEKDAY(A371),"Sun","Mon","Tue","Wed","Thu","Fri","Sat") -> Thu | C371: =IF(IFERROR(INDEX(Holidays!$D$5:$D$60,MATCH(A371,Holidays!$A$5:$A$60,0)),"")="Holiday","Holiday",IF(WEEKDAY(A371)>=6,"Weekend",IF(IFERROR(INDEX(Holidays!$D$5:$D$60,MATCH(A371,Holidays!$A$5:$A$60,0)),"")="Eve","Eve","Workday"))) -> Workday | D371: =IFERROR(INDEX(Holidays!$C$5:$C$60,MATCH(A371,Holidays!$A$5:$A$60,0)),"") | K371: =IF(E371<>"",E371,IF(U371,"Present",IF(C371="Holiday","Holiday","Weekend"))) -> Present | L371: =IF(OR(K371="Present",K371="Manual Work",K371="Partial Vacation",K371="Partial Sick Leave"),IF(ISNUMBER(F371),F371,IF(AND(K371="Present",U371),Settings!$B$6,"")),"") -> 0.33333333 | M371: =IF(OR(K371="Present",K371="Manual Work",K371="Partial Vacation",K371="Partial Sick Leave"),IF(ISNUMBER(G371),G371,IF(AND(K371="Present",U371),V371,"")),"") -> 0.6875 | N371: =IF(AND(ISNUMBER(L371),ISNUMBER(M371)),MAX(0,(M371-L371)*24),0) -> 8.5 | O371: =IF(NOT(U371),0,IF(K371="Vacation",IF(C371="Eve",Settings!$B$9*Settings!$B$11,W371),IF(K371="Partial Vacation",IF(AND(ISNUMBER(H371),ISNUMBER(I371)),MAX(0,(I371-H371)*24),0),0))) -> 0 | P371: =IF(NOT(U371),0,IF(K371="Sick Leave",W371,IF(K371="Partial Sick Leave",IF(AND(ISNUMBER(H371),ISNUMBER(I371)),MAX(0,(I371-H371)*24),0),0))) -> 0 | Q371: =IF(NOT(U371),0,IF(K371="Vacation",IF(C371="Eve",Settings!$B$11,1),IF(K371="Partial Vacation",O371/Settings!$B$9,0))) -> 0 | R371: =IF(NOT(U371),0,IF(K371="Sick Leave",1,IF(K371="Partial Sick Leave",P371/Settings!$B$9,0))) -> 0 | S371: =IF(AND(OR(E371="Vacation",E371="Sick Leave",E371="Partial Vacation",E371="Partial Sick Leave"),NOT(U371)),"Leave not allowed on this day",IF(AND(E371="Manual Work",OR(NOT(ISNUMBER(F371)),NOT(ISNUMBER(G371)))),"Enter start and end",IF(AND(OR(E371="Partial Vacation",E371="Partial Sick Leave"),OR(NOT(ISNUMBER(H371)),NOT(ISNUMBER(I371)))),"Enter leave from and to",IF(AND(ISNUMBER(F371),ISNUMBER(G371),G371<=F371),"End is before start",IF(AND(ISNUMBER(H371),ISNUMBER(I371),I371<=H371),"Leave end is before start",IF(AND(ISNUMBER(F371),ISNUMBER(G371),ISNUMBER(H371),ISNUMBER(I371),F371<I371,H371<G371),"Work and leave hours overlap",IF(AND(E371<>"",WEEKDAY(A371)=7),"Saturday - administrator only",""))))))) | T371: =MONTH(A371) -> 12 | U371: =OR(C371="Workday",C371="Eve") -> TRUE | V371: =IF(C371="Eve",Settings!$B$8,Settings!$B$7) -> 0.6875 | W371: =IF(U371,(V371-Settings!$B$6)*24,0) -> 8.5

Sheet Nir Ben Haim
A1: Attendance 2026 - Nir Ben Haim
A2: Fill in only the yellow cells, and only for days that differ from the automatic day.
A3: Vacation days | C3: Vacation hours | E3: Sick leave days | F3: Sick leave hours | H3: Days worked | J3: Worked hours | K3: Entries to check
A4: =SUM(Q7:Q371) -> 0 | C4: =SUM(O7:O371) -> 0 | E4: =SUM(R7:R371) -> 0 | F4: =SUM(P7:P371) -> 0 | H4: =COUNTIF(N7:N371,">0") -> 256 | J4: =SUM(N7:N371) -> 2166 | K4: =COUNTIF(S7:S371,"?*") -> 0
A6: Date | B6: Day | C6: Day type | D6: Holiday | E6: Status (leave empty = automatic) | F6: Start | G6: End | H6: Leave from | I6: Leave to | J6: Notes | K6: Applied status | L6: Applied start | M6: Applied end | N6: Worked hours | O6: Vacation hours | P6: Sick leave hours | Q6: Vacation days | R6: Sick leave days | S6: Check | T6: Month | U6: Working day | V6: Day end | W6: Full day hours
